Workbook

Sheet PLANILHA EXTRAÇÃO
C1: Estado de Santa Catarina
C2: Secretaria de Estado da Saúde
C3: Superintendência de Vigilância em Saúde
C4: Laboratório Central de Saúde Pública - LACEN
C5: Rastreabilidade: POP RT 5.5 BIMOL-167 Extratores automatizados (01/00)
B6: EXTRAÇÃO de RNA/DNA
B8: EXT/EQ/DATA | C8: EXT 49 EXTRACTA 18/07/2025
B9: 1 | C9: 2 | D9: 3 | E9: 4 | F9: 5 | G9: 6 | H9: 7 | I9: 8 | J9: 9 | K9: 10 | L9: 11 | M9: 12
A10: A | B10: 422386149R | C10: 422386273 | D10: 422386293 | E10: 422387159 | F10: 422386742 | G10: X | H10: X | I10: X | J10: X | K10: X | L10: X | M10: 422387224
A11: B | B11: 422386266R | C11: 422387254 | D11: 422386816 | E11: 422387129 | F11: 422385147 | G11: X | H11: X | I11: X | J11: X | K11: X | L11: X | M11: CP
A12: C | B12: 422386156R | C12: 422386806 | D12: 422386798 | E12: 422387065 | F12: X | G12: X | H12: X | I12: X | J12: X | K12: X | L12: X | M12: X
A13: D | B13: 422386625 | C13: 422386980 | D13: 422387130 | E13: 422387062 | F13: X | G13: X | H13: X | I13: X | J13: X | K13: X | L13: X | M13: X
A14: E | B14: 422386851 | C14: 422385450 | D14: 422386593 | E14: 422387059 | F14: X | G14: X | H14: X | I14: X | J14: X | K14: X | L14: X | M14: X
A15: F | B15: 422386866 | C15: 422386322 | D15: 422386852 | E15: 422387047 | F15: X | G15: X | H15: X | I15: X | J15: X | K15: X | L15: X | M15: X
A16: G | B16: 422386883 | C16: 422386324 | D16: 422386928 | E16: 422387071 | F16: X | G16: CN | H16: X | I16: X | J16: X | K16: X | L16: X | M16: X
A17: H | B17: 422386268 | C17: 422386282 | D17: 422387004 | E17: 422387075 | F17: X | G17: CP | H17: X | I17: X | J17: X | K17: X | L17: X | M17: X
B20: Agravos | C20: Colunas | E20: LEGENDA: | H20: Kit de Extração | L20: Etapa | M20: Responsável
B21: COVID | C21: 1 à 5 | E21: NA = Não se aplica | H21: Lote | I21: PT96PVMDX002 | L21: Manutenção | M21: KEILLEN
B22: ZDC | C22: 12 | E22: R = Repetição | H22: Validade | I22: 45748 | L22: Extração
E23: VR: Vírus respiratórios
E24: MEN: Meningite | H24: Controles
E25: SAR: Sarampo | H25: Lote
E26: ORO/MAY: Oropouche/Mayaro | H26: Validade
E27: HRP/MPX: Herpes/Monkeypox
E28: COQ: Coqueluche | H28: Montagem da planilha:
H29: Resp./data: | I29: PAULA 18/07/2025
B30: Obs: ______________________________________________________________________________________________________
B31: ___________________________________________________________________________________________________________________________________ | C31: COLUNA 12 SC TRANSPLANTE COVID
B32: ___________________________________________________________________________________________________________________________________

Sheet PLANILHA DETECÇÃO
D1: ESTADO DE SANTA CATARINA
D2: Secretaria de Estado da Saúde
D3: Superintendência de Vigilância em Saúde
D4: Laboratório Central de Saúde Pública - LACEN
D5: Rastreabilidade: _________________________________________________
B6: ______________________________________________________________
B8: RESPONSÁVEL PCR: ____________________________ | J8: Data PCR: | K8: ='PLANILHA EXTRAÇÃO'!J8 -> 0 | M8: Nome do arquivo: ___________________________________ | V8: Placa: | X8: ='PLANILHA EXTRAÇÃO'!M8 -> 0
B9: Extração/EQ: | D9: ='PLANILHA EXTRAÇÃO'!C8 -> EXT 49 EXTRACTA 18/07/2025 | M9: MIX EQ: _________ | Q9: Aplicação EQ: __________ | V9: EQ PCR: __________
B11: 1 | C11: R | D11: 2 | E11: R | F11: 3 | G11: R | H11: 4 | I11: R | J11: 5 | K11: R | L11: 6 | M11: R | N11: 7 | O11: R | P11: 8 | Q11: R | R11: 9 | S11: R | T11: 10 | U11: R | V11: 11 | W11: R | X11: 12 | Y11: R
A12: A | B12: ='PLANILHA EXTRAÇÃO'!B10 -> 422386149R | D12: ='PLANILHA EXTRAÇÃO'!C10 -> 422386273 | F12: ='PLANILHA EXTRAÇÃO'!D10 -> 422386293 | H12: ='PLANILHA EXTRAÇÃO'!E10 -> 422387159 | J12: ='PLANILHA EXTRAÇÃO'!F10 -> 422386742 | L12: ='PLANILHA EXTRAÇÃO'!G10 -> X | N12: ='PLANILHA EXTRAÇÃO'!H10 -> X | P12: ='PLANILHA EXTRAÇÃO'!I10 -> X | R12: ='PLANILHA EXTRAÇÃO'!J10 -> X | T12: ='PLANILHA EXTRAÇÃO'!K10 -> X | V12: ='PLANILHA EXTRAÇÃO'!L10 -> X | X12: ='PLANILHA EXTRAÇÃO'!M10 -> 422387224
A14: B | B14: ='PLANILHA EXTRAÇÃO'!B11 -> 422386266R | D14: ='PLANILHA EXTRAÇÃO'!C11 -> 422387254 | F14: ='PLANILHA EXTRAÇÃO'!D11 -> 422386816 | H14: ='PLANILHA EXTRAÇÃO'!E11 -> 422387129 | J14: ='PLANILHA EXTRAÇÃO'!F11 -> 422385147 | L14: ='PLANILHA EXTRAÇÃO'!G11 -> X | N14: ='PLANILHA EXTRAÇÃO'!H11 -> X | P14: ='PLANILHA EXTRAÇÃO'!I11 -> X | R14: ='PLANILHA EXTRAÇÃO'!J11 -> X | T14: ='PLANILHA EXTRAÇÃO'!K11 -> X | V14: ='PLANILHA EXTRAÇÃO'!L11 -> X | X14: ='PLANILHA EXTRAÇÃO'!M11 -> CP
A16: C | B16: ='PLANILHA EXTRAÇÃO'!B12 -> 422386156R | D16: ='PLANILHA EXTRAÇÃO'!C12 -> 422386806 | F16: ='PLANILHA EXTRAÇÃO'!D12 -> 422386798 | H16: ='PLANILHA EXTRAÇÃO'!E12 -> 422387065 | J16: ='PLANILHA EXTRAÇÃO'!F12 -> X | L16: ='PLANILHA EXTRAÇÃO'!G12 -> X | N16: ='PLANILHA EXTRAÇÃO'!H12 -> X | P16: ='PLANILHA EXTRAÇÃO'!I12 -> X | R16: ='PLANILHA EXTRAÇÃO'!J12 -> X | T16: ='PLANILHA EXTRAÇÃO'!K12 -> X | V16: ='PLANILHA EXTRAÇÃO'!L12 -> X | X16: ='PLANILHA EXTRAÇÃO'!M12 -> X
A18: D | B18: ='PLANILHA EXTRAÇÃO'!B13 -> 422386625 | D18: ='PLANILHA EXTRAÇÃO'!C13 -> 422386980 | F18: ='PLANILHA EXTRAÇÃO'!D13 -> 422387130 | H18: ='PLANILHA EXTRAÇÃO'!E13 -> 422387062 | J18: ='PLANILHA EXTRAÇÃO'!F13 -> X | L18: ='PLANILHA EXTRAÇÃO'!G13 -> X | N18: ='PLANILHA EXTRAÇÃO'!H13 -> X | P18: ='PLANILHA EXTRAÇÃO'!I13 -> X | R18: ='PLANILHA EXTRAÇÃO'!J13 -> X | T18: ='PLANILHA EXTRAÇÃO'!K13 -> X | V18: ='PLANILHA EXTRAÇÃO'!L13 -> X | X18: ='PLANILHA EXTRAÇÃO'!M13 -> X
A20: E | B20: ='PLANILHA EXTRAÇÃO'!B14 -> 422386851 | D20: ='PLANILHA EXTRAÇÃO'!C14 -> 422385450 | F20: ='PLANILHA EXTRAÇÃO'!D14 -> 422386593 | H20: ='PLANILHA EXTRAÇÃO'!E14 -> 422387059 | J20: ='PLANILHA EXTRAÇÃO'!F14 -> X | L20: ='PLANILHA EXTRAÇÃO'!G14 -> X | N20: ='PLANILHA EXTRAÇÃO'!H14 -> X | P20: ='PLANILHA EXTRAÇÃO'!I14 -> X | R20: ='PLANILHA EXTRAÇÃO'!J14 -> X | T20: ='PLANILHA EXTRAÇÃO'!K14 -> X | V20: ='PLANILHA EXTRAÇÃO'!L14 -> X | X20: ='PLANILHA EXTRAÇÃO'!M14 -> X
A22: F | B22: ='PLANILHA EXTRAÇÃO'!B15 -> 422386866 | D22: ='PLANILHA EXTRAÇÃO'!C15 -> 422386322 | F22: ='PLANILHA EXTRAÇÃO'!D15 -> 422386852 | H22: ='PLANILHA EXTRAÇÃO'!E15 -> 422387047 | J22: ='PLANILHA EXTRAÇÃO'!F15 -> X | L22: ='PLANILHA EXTRAÇÃO'!G15 -> X | N22: ='PLANILHA EXTRAÇÃO'!H15 -> X | P22: ='PLANILHA EXTRAÇÃO'!I15 -> X | R22: ='PLANILHA EXTRAÇÃO'!J15 -> X | T22: ='PLANILHA EXTRAÇÃO'!K15 -> X | V22: ='PLANILHA EXTRAÇÃO'!L15 -> X | X22: ='PLANILHA EXTRAÇÃO'!M15 -> X
A24: G | B24: ='PLANILHA EXTRAÇÃO'!B16 -> 422386883 | D24: ='PLANILHA EXTRAÇÃO'!C16 -> 422386324 | F24: ='PLANILHA EXTRAÇÃO'!D16 -> 422386928 | H24: ='PLANILHA EXTRAÇÃO'!E16 -> 422387071 | J24: ='PLANILHA EXTRAÇÃO'!F16 -> X | L24: ='PLANILHA EXTRAÇÃO'!G16 -> CN | N24: ='PLANILHA EXTRAÇÃO'!H16 -> X | P24: ='PLANILHA EXTRAÇÃO'!I16 -> X | R24: ='PLANILHA EXTRAÇÃO'!J16 -> X | T24: ='PLANILHA EXTRAÇÃO'!K16 -> X | V24: ='PLANILHA EXTRAÇÃO'!L16 -> X | X24: ='PLANILHA EXTRAÇÃO'!M16 -> X
A26: H | B26: ='PLANILHA EXTRAÇÃO'!B17 -> 422386268 | D26: ='PLANILHA EXTRAÇÃO'!C17 -> 422386282 | F26: ='PLANILHA EXTRAÇÃO'!D17 -> 422387004 | H26: ='PLANILHA EXTRAÇÃO'!E17 -> 422387075 | J26: ='PLANILHA EXTRAÇÃO'!F17 -> X | L26: ='PLANILHA EXTRAÇÃO'!G17 -> CP | N26: ='PLANILHA EXTRAÇÃO'!H17 -> X | P26: ='PLANILHA EXTRAÇÃO'!I17 -> X | R26: ='PLANILHA EXTRAÇÃO'!J17 -> X | T26: ='PLANILHA EXTRAÇÃO'!K17 -> X | V26: ='PLANILHA EXTRAÇÃO'!L17 -> X | X26: ='PLANILHA EXTRAÇÃO'!M17 -> X
B28: ↓ Ordem de leitura: | P28: Validação (CONTROLES)
F29: OBS: _____________________________________________________ | S29: RESULTADO:
F30: __________________________________________________________ | S30: Interpretação/Resp: _____________________
F31: __________________________________________________________ | S31: Digitação/Resp: ________________________
F32: __________________________________________________________ | S32: Liberação/Resp: ________________________
D34: ESTADO DE SANTA CATARINA
D35: Secretaria de Estado da Saúde
D36: Superintendência de Vigilância em Saúde
D37: Laboratório Central de Saúde Pública - LACEN
D38: Rastreabilidade: ____________________________________________________________________
B39: _________________________________________________________________
B41: MIX | E41: VOL X 1 | G41: VOL X 96 | I41: VOL X _____ | N41: CICLAGEM | V41: LEGENDA:
B42: Mistura de PCR | E42: ____ µl | G42: ___ µL | N42: Temperatura | Q42: Duração | V42: D: Detectável
B43: Mix oligos | E43: ____ µL | G43: ___ µL | N43: __°C | Q43: __ min | V43: ND: Não detectável
B44: Total | E44: ____ µL | G44: ___ µL | N44: __°C | Q44: __ min | V44: CP: Controle positivo
B45: Usar o vortex e dar spin nos reagentes antes de fazer o mix. | N45: __ ciclos | O45: __°C | Q45: __ seg | V45: CN: Controle Negativo
B46: Volume Mix na placa: __ µL | O46: __°C | Q46: __ seg | V46: R: Resultado
B47: Volume amostra: __ µL | V47: Ok: Dentro dos limites
V48: FA: for a dos limites
V49: NT: Não testado
B51: KIT: _________________________________________________ | K51: LOTE: __________________________ | Q51: VALIDADE: ___________________________
B54: Critérios de aceitação dos controles negativo e positivo: | N54: Interpretação dos resultados:
B62: Validação (CONTROLES)
...
